try{
    let x = 10;
    miFuncionPrueba();
}catch(error){
    console.log("Dio error tu código: "+error);
}finally{
    console.log('termina la revisión de errores');
}

    
console.log("continuamos...");

    

